2024-12-24 13:01:15,116 INFO    MainThread:18016 [wandb_setup.py:_flush():68] Current SDK version is 0.19.0
2024-12-24 13:01:15,120 INFO    MainThread:18016 [wandb_setup.py:_flush():68] Configure stats pid to 18016
2024-12-24 13:01:15,122 INFO    MainThread:18016 [wandb_setup.py:_flush():68] Loading settings from C:\Users\User\.config\wandb\settings
2024-12-24 13:01:15,122 INFO    MainThread:18016 [wandb_setup.py:_flush():68] Loading settings from C:\Users\User\Documents\herbskeeper\HerbKeeper\wandb\settings
2024-12-24 13:01:15,124 INFO    MainThread:18016 [wandb_setup.py:_flush():68] Loading settings from environment variables
2024-12-24 13:01:15,126 INFO    MainThread:18016 [wandb_init.py:_log_setup():528] Logging user logs to C:\Users\User\Documents\herbskeeper\HerbKeeper\wandb\run-20241224_130115-Herb_Keeper 400\logs\debug.log
2024-12-24 13:01:15,129 INFO    MainThread:18016 [wandb_init.py:_log_setup():529] Logging internal logs to C:\Users\User\Documents\herbskeeper\HerbKeeper\wandb\run-20241224_130115-Herb_Keeper 400\logs\debug-internal.log
2024-12-24 13:01:15,130 INFO    MainThread:18016 [wandb_init.py:init():639] calling init triggers
2024-12-24 13:01:15,132 INFO    MainThread:18016 [wandb_init.py:init():645] wandb.init called with sweep_config: {}
config: {'name': 'Herb_Keeper DDQN 400', 'checkpoint': 'Data/checkpoint400.pth', 'learning_rate': 0.001, 'Schedule': 'Counter({5000000: 1, 10000000: 1, 15000000: 1, 20000000: 1, 25000000: 1, 30000000: 1}) gamma=0.5', 'epochs': 200000, 'start_epoch': 0, 'decay': 0, 'gamma': 0.99, 'batch_size': 128, 'C': 3, 'tau': 0.001, 'Model': 'DQN(\n  (linear1): Linear(in_features=123, out_features=128, bias=True)\n  (linear2): Linear(in_features=128, out_features=64, bias=True)\n  (output): Linear(in_features=64, out_features=40, bias=True)\n)', 'device': 'cpu'}
2024-12-24 13:01:15,133 INFO    MainThread:18016 [wandb_init.py:init():688] starting backend
2024-12-24 13:01:15,134 INFO    MainThread:18016 [wandb_init.py:init():692] sending inform_init request
2024-12-24 13:01:15,243 INFO    MainThread:18016 [backend.py:_multiprocessing_setup():104] multiprocessing start_methods=spawn, using: spawn
2024-12-24 13:01:15,249 INFO    MainThread:18016 [wandb_init.py:init():705] backend started and connected
2024-12-24 13:01:15,265 INFO    MainThread:18016 [wandb_init.py:init():798] updated telemetry
2024-12-24 13:01:15,460 INFO    MainThread:18016 [wandb_init.py:init():830] communicating run to backend with 90.0 second timeout
2024-12-24 13:01:23,843 INFO    Thread-12 (wrapped_target):18016 [retry.py:__call__():172] Retry attempt failed:
Traceback (most recent call last):
  File "C:\Python311\Lib\site-packages\urllib3\connection.py", line 200, in _new_conn
    sock = connection.create_connection(
           ^^^^^^^^^^^^^^^^^^^^^^^^^^^^^
  File "C:\Python311\Lib\site-packages\urllib3\util\connection.py", line 60, in create_connection
    for res in socket.getaddrinfo(host, port, family, socket.SOCK_STREAM):
               ^^^^^^^^^^^^^^^^^^^^^^^^^^^^^^^^^^^^^^^^^^^^^^^^^^^^^^^^^^
  File "C:\Python311\Lib\socket.py", line 962, in getaddrinfo
    for res in _socket.getaddrinfo(host, port, family, type, proto, flags):
               ^^^^^^^^^^^^^^^^^^^^^^^^^^^^^^^^^^^^^^^^^^^^^^^^^^^^^^^^^^^
socket.gaierror: [Errno 11001] getaddrinfo failed

The above exception was the direct cause of the following exception:

Traceback (most recent call last):
  File "C:\Python311\Lib\site-packages\urllib3\connectionpool.py", line 790, in urlopen
    response = self._make_request(
               ^^^^^^^^^^^^^^^^^^^
  File "C:\Python311\Lib\site-packages\urllib3\connectionpool.py", line 491, in _make_request
    raise new_e
  File "C:\Python311\Lib\site-packages\urllib3\connectionpool.py", line 467, in _make_request
    self._validate_conn(conn)
  File "C:\Python311\Lib\site-packages\urllib3\connectionpool.py", line 1092, in _validate_conn
    conn.connect()
  File "C:\Python311\Lib\site-packages\urllib3\connection.py", line 604, in connect
    self.sock = sock = self._new_conn()
                       ^^^^^^^^^^^^^^^^
  File "C:\Python311\Lib\site-packages\urllib3\connection.py", line 207, in _new_conn
    raise NameResolutionError(self.host, self, e) from e
urllib3.exceptions.NameResolutionError: <urllib3.connection.HTTPSConnection object at 0x000001C1ECF19650>: Failed to resolve 'api.wandb.ai' ([Errno 11001] getaddrinfo failed)

The above exception was the direct cause of the following exception:

Traceback (most recent call last):
  File "C:\Python311\Lib\site-packages\requests\adapters.py", line 486, in send
    resp = conn.urlopen(
           ^^^^^^^^^^^^^
  File "C:\Python311\Lib\site-packages\urllib3\connectionpool.py", line 844, in urlopen
    retries = retries.increment(
              ^^^^^^^^^^^^^^^^^^
  File "C:\Python311\Lib\site-packages\urllib3\util\retry.py", line 515, in increment
    raise MaxRetryError(_pool, url, reason) from reason  # type: ignore[arg-type]
    ^^^^^^^^^^^^^^^^^^^^^^^^^^^^^^^^^^^^^^^^^^^^^^^^^^^
urllib3.exceptions.MaxRetryError: HTTPSConnectionPool(host='api.wandb.ai', port=443): Max retries exceeded with url: /graphql (Caused by NameResolutionError("<urllib3.connection.HTTPSConnection object at 0x000001C1ECF19650>: Failed to resolve 'api.wandb.ai' ([Errno 11001] getaddrinfo failed)"))

During handling of the above exception, another exception occurred:

Traceback (most recent call last):
  File "C:\Python311\Lib\site-packages\wandb\sdk\lib\retry.py", line 131, in __call__
    result = self._call_fn(*args, **kwargs)
             ^^^^^^^^^^^^^^^^^^^^^^^^^^^^^^
  File "C:\Python311\Lib\site-packages\wandb\sdk\internal\internal_api.py", line 393, in execute
    return self.client.execute(*args, **kwargs)  # type: ignore
           ^^^^^^^^^^^^^^^^^^^^^^^^^^^^^^^^^^^^
  File "C:\Python311\Lib\site-packages\wandb\vendor\gql-0.2.0\wandb_gql\client.py", line 52, in execute
    result = self._get_result(document, *args, **kwargs)
             ^^^^^^^^^^^^^^^^^^^^^^^^^^^^^^^^^^^^^^^^^^^
  File "C:\Python311\Lib\site-packages\wandb\vendor\gql-0.2.0\wandb_gql\client.py", line 60, in _get_result
    return self.transport.execute(document, *args, **kwargs)
           ^^^^^^^^^^^^^^^^^^^^^^^^^^^^^^^^^^^^^^^^^^^^^^^^^
  File "C:\Python311\Lib\site-packages\wandb\sdk\lib\gql_request.py", line 58, in execute
    request = self.session.post(self.url, **post_args)
              ^^^^^^^^^^^^^^^^^^^^^^^^^^^^^^^^^^^^^^^^
  File "C:\Python311\Lib\site-packages\requests\sessions.py", line 637, in post
    return self.request("POST", url, data=data, json=json, **kwargs)
           ^^^^^^^^^^^^^^^^^^^^^^^^^^^^^^^^^^^^^^^^^^^^^^^^^^^^^^^^^
  File "C:\Python311\Lib\site-packages\requests\sessions.py", line 589, in request
    resp = self.send(prep, **send_kwargs)
           ^^^^^^^^^^^^^^^^^^^^^^^^^^^^^^
  File "C:\Python311\Lib\site-packages\requests\sessions.py", line 703, in send
    r = adapter.send(request, **kwargs)
        ^^^^^^^^^^^^^^^^^^^^^^^^^^^^^^^
  File "C:\Python311\Lib\site-packages\requests\adapters.py", line 519, in send
    raise ConnectionError(e, request=request)
requests.exceptions.ConnectionError: HTTPSConnectionPool(host='api.wandb.ai', port=443): Max retries exceeded with url: /graphql (Caused by NameResolutionError("<urllib3.connection.HTTPSConnection object at 0x000001C1ECF19650>: Failed to resolve 'api.wandb.ai' ([Errno 11001] getaddrinfo failed)"))
